Workbook

Sheet Сomposition
J1: MMP - Multipurpose mobile platform - parts and assemblies
A2: 3D-model | B2: PDF | C2: Dxf | D2: STEP | E2: Drawing | F2: 3D-PDF | G2: № | H2: Part number | K2: Description | L2: Q-ty for 1 platform | M2: Material | N2: Covering | O2: Notes
A3: =TRUE() -> TRUE | B3: =FALSE() -> FALSE | C3: =FALSE() -> FALSE | D3: =TRUE() -> TRUE | E3: =FALSE() -> FALSE | F3: =FALSE() -> FALSE | G3: 0.0.0 | H3: MMP.00.00.00.000 | K3: Multipurpose mobile platform | L3: 1
A4: =TRUE() -> TRUE | B4: =TRUE() -> TRUE | C4: =TRUE() -> TRUE | D4: =TRUE() -> TRUE | E4: =TRUE() -> TRUE | F4: =FALSE() -> FALSE | G4: 0.0.1 | H4: MMP.00.00.00.001 | K4: Front panel | L4: 1 | M4: Steel EN 1.0114, s2 | N4: RAL9016
A5: =TRUE() -> TRUE | B5: =TRUE() -> TRUE | C5: =TRUE() -> TRUE | D5: =TRUE() -> TRUE | E5: =TRUE() -> TRUE | F5: =FALSE() -> FALSE | G5: 0.0.2 | H5: MMP.00.00.00.002 | K5: Back panel | L5: 1 | M5: Steel EN 1.0114, s2 | N5: RAL9016
A6: =TRUE() -> TRUE | B6: =TRUE() -> TRUE | C6: =TRUE() -> TRUE | D6: =TRUE() -> TRUE | E6: =TRUE() -> TRUE | F6: =FALSE() -> FALSE | G6: 0.0.3 | H6: MMP.00.00.00.003 | K6: Side panel | L6: 2 | M6: Steel EN 1.0114, s0,8 | N6: RAL9016
A7: =TRUE() -> TRUE | B7: =FALSE() -> FALSE | C7: =FALSE() -> FALSE | D7: =TRUE() -> TRUE | E7: =FALSE() -> FALSE | F7: =FALSE() -> FALSE | G7: 0.0.4 | H7: РТ1.00.00.032 | K7: Camera upper body | L7: 1 | O7: 3d-printing
A8: =TRUE() -> TRUE | B8: =FALSE() -> FALSE | C8: =FALSE() -> 0 | D8: =TRUE() -> TRUE | E8: =FALSE() -> FALSE | F8: =TRUE() -> TRUE | G8: 1 | H8: MMP.01.00.00.000 | K8: Cover assembly | L8: 1
A9: =TRUE() -> TRUE | B9: =TRUE() -> TRUE | C9: =TRUE() -> TRUE | D9: =TRUE() -> TRUE | E9: =TRUE() -> TRUE | F9: =FALSE() -> FALSE | G9: 1.1 | I9: MMP.01.00.00.001 | K9: Cover | L9: 1 | M9: Steel EN 1.0114, s0,8 | N9: RAL9016
A10: =TRUE() -> TRUE | B10: =TRUE() -> TRUE | C10: =TRUE() -> TRUE | D10: =TRUE() -> TRUE | E10: =TRUE() -> TRUE | F10: =FALSE() -> FALSE | G10: 1.2 | I10: MMP.01.00.00.002 | K10: Cover flange | L10: 2 | M10: Steel EN 1.0114, s0,8 | N10: RAL9016
A11: =TRUE() -> TRUE | B11: =FALSE() -> FALSE | C11: =FALSE() -> 0 | D11: =TRUE() -> TRUE | E11: =FALSE() -> FALSE | F11: =TRUE() -> TRUE | G11: 2 | H11: MMP.02.00.00.000 | K11: Base assembly | L11: 1
A12: =TRUE() -> TRUE | B12: =TRUE() -> TRUE | C12: =TRUE() -> TRUE | D12: =TRUE() -> TRUE | E12: =TRUE() -> TRUE | F12: =FALSE() -> FALSE | G12: 2.1 | I12: MMP.02.00.00.001 | K12: Base | M12: Steel EN 1.0114, s2 | N12: RAL9016
A13: =TRUE() -> TRUE | B13: =FALSE() -> FALSE | C13: =FALSE() -> FALSE | D13: =TRUE() -> TRUE | E13: =FALSE() -> FALSE | F13: =TRUE() -> TRUE | G13: 3 | H13: MMP.03.00.00.000 | K13: Wheel assembly | L13: 2
A14: =TRUE() -> TRUE | B14: =TRUE() -> TRUE | C14: =TRUE() -> TRUE | D14: =TRUE() -> TRUE | E14: =TRUE() -> TRUE | F14: =FALSE() -> FALSE | G14: 3.1 | I14: MMP.03.00.00.001 | K14: Wheel bracket outer | L14: 2 | M14: Steel EN 1.0114, s2 | N14: RAL9016 | O14: Threaded holes (М3, М4)
A15: =TRUE() -> TRUE | B15: =TRUE() -> TRUE | C15: =TRUE() -> TRUE | D15: =TRUE() -> TRUE | E15: =TRUE() -> TRUE | F15: =FALSE() -> FALSE | G15: 3.2 | I15: MMP.03.00.00.002 | K15: Wheel bracket inner | L15: 2 | M15: Steel EN 1.0114, s2 | N15: RAL9016 | O15: Threaded holes (М4)
A16: =TRUE() -> TRUE | B16: =TRUE() -> TRUE | C16: =TRUE() -> TRUE | D16: =TRUE() -> TRUE | E16: =TRUE() -> TRUE | F16: =FALSE() -> FALSE | G16: 3.3 | I16: MMP.03.00.00.003 | K16: Motor bracket | L16: 2 | M16: Steel EN 1.0114, s2 | N16: RAL9016
A17: =TRUE() -> TRUE | B17: =TRUE() -> TRUE | C17: =FALSE() -> FALSE | D17: =TRUE() -> TRUE | E17: =TRUE() -> TRUE | F17: =FALSE() -> FALSE | G17: 3.4 | I17: MMP.03.00.00.004 | K17: Drive shaft | L17: 2 | M17: Steel 37Cr4
A18: =TRUE() -> TRUE | B18: =FALSE() -> FALSE | C18: =FALSE() -> FALSE | D18: =TRUE() -> TRUE | E18: =FALSE() -> FALSE | F18: =TRUE() -> TRUE | G18: 3.5 | I18: РТ1.00.00.240 | K18: Magnetic encoder | L18: 2
A19: =TRUE() -> TRUE | B19: =FALSE() -> FALSE | C19: =FALSE() -> FALSE | D19: =TRUE() -> TRUE | E19: =FALSE() -> FALSE | F19: =FALSE() -> FALSE | G19: 3.5.1 | J19: РТ1.00.00.241 | K19: Adapter | L19: 2 | O19: 3d-printing
A20: =TRUE() -> TRUE | B20: =FALSE() -> FALSE | C20: =FALSE() -> FALSE | D20: =TRUE() -> TRUE | E20: =FALSE() -> FALSE | F20: =FALSE() -> FALSE | G20: 3.5.2 | J20: РТ1.00.00.242 | K20: Bracket | L20: 2 | O20: 3d-printing
A21: =TRUE() -> TRUE | B21: =FALSE() -> FALSE | C21: =FALSE() -> FALSE | D21: =TRUE() -> TRUE | E21: =FALSE() -> FALSE | F21: =FALSE() -> FALSE | G21: 3.5.3 | J21: РТ1.00.00.243 | K21: Cover | L21: 2 | O21: 3d-printing
A22: =TRUE() -> TRUE | B22: =FALSE() -> FALSE | C22: =FALSE() -> FALSE | D22: =TRUE() -> TRUE | E22: =FALSE() -> FALSE | F22: =TRUE() -> TRUE | G22: 4 | H22: MMP.04.00.00.000 | K22: Center bracket assembly | L22: 1
A23: =TRUE() -> TRUE | B23: =TRUE() -> TRUE | C23: =TRUE() -> TRUE | D23: =TRUE() -> TRUE | E23: =TRUE() -> TRUE | F23: =FALSE() -> FALSE | G23: 4.1 | I23: MMP.04.00.00.001 | K23: Center bracket | M23: Steel EN 1.0114, s2 | N23: RAL9016
A24: =TRUE() -> TRUE | B24: =FALSE() -> FALSE | C24: =FALSE() -> FALSE | D24: =TRUE() -> TRUE | E24: =FALSE() -> FALSE | F24: =TRUE() -> TRUE | G24: 5 | H24: MMP.05.00.00.000 | K24: Support assembly | L24: 2
A25: =TRUE() -> TRUE | B25: =TRUE() -> TRUE | C25: =TRUE() -> TRUE | D25: =TRUE() -> TRUE | E25: =TRUE() -> TRUE | F25: =FALSE() -> FALSE | G25: 5.1 | I25: MMP.05.00.00.001 | K25: Support | M25: Steel EN 1.0114, s1,2 | N25: RAL9016
A26: =TRUE() -> TRUE | B26: =FALSE() -> FALSE | C26: =FALSE() -> FALSE | D26: =TRUE() -> TRUE | E26: =FALSE() -> FALSE | F26: =TRUE() -> TRUE | G26: 6 | H26: MMP.05.00.00.000-01 | K26: Support assembly | L26: 2
A27: =TRUE() -> TRUE | B27: =TRUE() -> TRUE | C27: =TRUE() -> TRUE | D27: =TRUE() -> TRUE | E27: =TRUE() -> TRUE | F27: =FALSE() -> FALSE | G27: 6.1 | I27: MMP.05.00.00.001-01 | K27: Support | M27: Steel EN 1.0114, s1,2 | N27: RAL9016
A28: =TRUE() -> TRUE | B28: =FALSE() -> FALSE | C28: =FALSE() -> FALSE | D28: =TRUE() -> TRUE | E28: =FALSE() -> FALSE | F28: =TRUE() -> TRUE | G28: 7 | H28: MMP.07.00.00.000 | K28: Lidar support assembly | L28: 1
A29: =TRUE() -> TRUE | B29: =TRUE() -> TRUE | C29: =TRUE() -> TRUE | D29: =TRUE() -> TRUE | E29: =TRUE() -> TRUE | F29: =FALSE() -> FALSE | G29: 7.1 | I29: MMP.07.00.00.001 | K29: Lidar support | M29: Steel EN 1.0114, s1,2 | N29: RAL9016
H30: - 3D-printed part

Sheet Components
A1: № | B1: Description | D1: Q-ty for 1 platform, pcs | E1: Link | F1: Part No. | G1: Additional info
A2: 1 | B2: Heavy duty drive wheel | C2: Blickle GEVN 200/30H7 | D2: 2 | E2: Link | F2: 4047526113377 | G2: Catalogue
A3: 2 | B3: Light duty swivel castor | C3: Blickle LPA-VSTH 35K | D3: 4 | E3: Link | F3: 4047526603175
A4: 3 | B4: Oval flange bearing units | C4: REXNORD UCFL 205 C 655472 (d25) | D4: 2 | E4: Link | F4: 655472
A5: 4 | B5: Oval flange bearing units | C5: REXNORD UCFL 206 C 666412 (d30) | D5: 2 | E5: Link | F5: 666412
A6: 5 | B6: Rivet Nut - M4 | C6: Blind Rivet Nut - Round Thin - Stainless Steel - M4 | D6: ='Applicability of fasteners'!F23 -> 58 | E6: Link | F6: 100 - 5802159
A7: 6 | B7: Rivet Nut - M5 | C7: Blind Rivet Nut - Round Thin - Stainless Steel - M5 | D7: ='Applicability of fasteners'!G23 -> 48 | E7: Link | F7: 100 - 5802287
A8: 7 | B8: Rivet Nut - M6 | C8: Blind Rivet Nut - Round Thin - Stainless Steel - M6 | D8: ='Applicability of fasteners'!H23 -> 16 | E8: Link | F8: 100 - 5802253
A9: 8 | B9: Rivet Nut - M8 | C9: Blind Rivet Nut - Round Thin - Stainless Steel - M8 | D9: ='Applicability of fasteners'!I23 -> 8 | E9: Link | F9: 100 - 5802182
A10: 9 | B10: Feather key | C10: Feather key 4x4x25 DIN 6885-UNI 6604 (former ISO 773) | D10: 2 | E10: Link
A11: 10 | B11: Feather key | C11: Feather key 8x7x28 DIN 6885-UNI 6604 (former ISO 773) | D11: 2
A12: 11 | B12: Screwed spacer sleeve | C12: TFF-M3/25 FIX&FASTEN | D12: 4 | E12: Link
A13: 12 | B13: BLDC motor | C13: Z4BLD60-24GN-30S/4GN 25K | D13: 2
A14: 13 | B14: Laser Range Scanner | C14: RPLIDAR A1-A1M8 | D14: 1 | E14: Link
A15: 14 | B15: Camera | C15: Camera Module NVision Assem | D15: 1
A16: 14 | B16: Proximity Sensor | C16: E18-D80NK | D16: 4 | E16: Link
A17: 15 | B17: US Sensor | C17: JSN-SR04T | D17: 1
A18: 16 | B18: LED module | C18: 3 LED RGB Module 0.72W SWP | D18: 2

Sheet Applicability of fasteners
A1: MMP - Applicability of fasteners
A3: № | B3: Part number | C3: Description | D3: Q-ty, pcs | E3: 3D PDF | F3: Blind Rivet Nut - Round Thin - Stainless Steel - M4 | G3: Blind Rivet Nut - Round Thin - Stainless Steel - M5 | H3: Blind Rivet Nut - Round Thin - Stainless Steel - M6 | I3: Blind Rivet Nut - Round Thin - Stainless Steel - M8 | J3: Blind rivet Al/St 4,0х8, DIN 7337 | K3: Screw М4x16 DIN 912 | L3: Screw М5x20 DIN 912 | M3: Screw М5x70 DIN 912 | N3: Screw М6x20 DIN 912 | O3: Screw М10x45 DIN 912 | P3: Screw М3x12 DIN 965 | Q3: Screw М3x8 DIN 966 | R3: Screw М3x12 DIN 967 | S3: Screw М4x12 DIN 967 | T3: Screw М4x16 DIN 967 | U3: Screw М8x25 DIN 967 | V3: Screw М2x8 DIN 7985 | W3: Screw М2x16 DIN 7985 | X3: Screw М2,5x6 DIN 7985 | Y3: Screw М3x8 DIN 7985 | Z3: Screw М4x16 DIN 7985 | AA3: Nut M2 DIN 934 | AB3: Nut M3 DIN 934 | AC3: Nut M10 DIN 934 | AD3: Washer 2 DIN 125 | AE3: Washer 2,5 DIN 125 | AF3: Washer 3 DIN 125 | AG3: Washer 4 DIN 125 | AH3: Washer 5 DIN 125 | AI3: Washer 6 DIN 125 | AJ3: Washer 8 DIN 125 | AK3: Washer 10 DIN 125 | AL3: Spring lock washer 2 DIN 7980 | AM3: Spring lock washer 2,5 DIN 7980 | AN3: Spring lock washer 3 DIN 7980 | AO3: Spring lock washer 4 DIN 7980 | AP3: Spring lock washer 5 DIN 7980 | AQ3: Spring lock washer 6 DIN 7980 | AR3: Spring lock washer 10 DIN 7980 | AS3: Large size washer 4 DIN 9021 | AT3: Screwed spacer sleeve TFF-M3/25 | AU3: Feather key 4x4x25 DIN 6885-UNI 6604 (former ISO 773) | AV3: Feather key 8x7x28 DIN 6885-UNI 6604 (former ISO 773)
A4: 1.1 | B4: Main assembly | C4: Camera to Front panel | Q4: 4 | R4: 4 | W4: 4 | AA4: 4 | AD4: 4 | AF4: 16 | AL4: 4 | AT4: 4
A5: 1.2 | C5: Cover to Center bracket | U5: 4 | AJ5: 4
A6: 1.3 | C6: Lidar to support assembly | X6: 4 | AE6: 4 | AM6: 4
A7: 1.4 | C7: Lidar support assembly to base | Z7: 4 | AG7: 4 | AO7: 4
A8: 1.5 | C8: Center bracket to base | L8: 16 | AH8: 16 | AP8: 16
A9: 1.6 | C9: Side panels | S9: 32
A10: 1.7 | C10: Front panel - up | S10: 4
A11: 1.8 | C11: Front panel - down | T11: 10
A12: 1.9 | C12: Support assemblies to base | K12: 8 | AO12: 8 | AS12: 8
A13: 1.10 | C13: Light duty swivel castors to base | N13: 16 | AI13: 16 | AQ13: 16
A14: 1.11 | C14: Wheel assemblies to base | L14: 16 | AH14: 16 | AP14: 16
A15: 2 | B15: MMP.01.00.00.000 | C15: Cover assembly | D15: 1 | Y15: 10 | AB15: 10 | AF15: 20 | AN15: 10
A16: 3 | B16: MMP.02.00.00.000 | C16: Base assembly | D16: 1 | F16: 26 | H16: 16
A17: 4 | B17: MMP.03.00.00.000 | C17: Wheel assembly | D17: 2 | F17: 8 | G17: 40 | L17: 8 | M17: 8 | O17: 8 | P17: 4 | AB17: 4 | AC17: 8 | AH17: 16 | AK17: 12 | AR17: 8 | AU17: 2 | AV17: 2
A18: 4.1 | B18: РТ1.00.00.240 | C18: Magnetic encoder | D18: 2 | V18: 8 | AA18: 8
A19: 6 | B19: MMP.04.00.00.000 | C19: Center bracket assembly | D19: 1 | G19: 8 | I19: 8 | J19: 16
A20: 7 | B20: MMP.05.00.00.000 | C20: Support assembly | D20: 2 | F20: 10
A21: 8 | B21: MMP.05.00.00.000-01 | C21: Support assembly | D21: 2 | F21: 10
A22: 9 | B22: MMP.07.00.00.000 | C22: Lidar support assembly | D22: 1 | F22: 4
C23: Total: | F23: =SUM(F4:F22) -> 58 | G23: =SUM(G4:G22) -> 48 | H23: =SUM(H4:H22) -> 16 | I23: =SUM(I4:I22) -> 8 | J23: =SUM(J4:J22) -> 16 | K23: =SUM(K4:K22) -> 8 | L23: =SUM(L4:L22) -> 40 | M23: =SUM(M4:M22) -> 8 | ... AV23: =SUM(AV4:AV22) -> 2

Sheet General list of fasteners
A1: № | B1: Description | C1: Q-ty, pcs
A2: 1 | B2: Screw М4x16 DIN 912 | C2: ='Applicability of fasteners'!K23 -> 8
A3: 2 | B3: Screw М5x20 DIN 912 | C3: ='Applicability of fasteners'!L23 -> 40
A4: 3 | B4: Screw М5x70 DIN 912 | C4: ='Applicability of fasteners'!M23 -> 8
A5: 4 | B5: Screw М6x20 DIN 912 | C5: ='Applicability of fasteners'!N23 -> 16
A6: 5 | B6: Screw М10x45 DIN 912 | C6: ='Applicability of fasteners'!O23 -> 8
A7: 6 | B7: Screw М3x12 DIN 965 | C7: ='Applicability of fasteners'!P23 -> 4
A8: 7 | B8: Screw М3x8 DIN 966 | C8: ='Applicability of fasteners'!Q23 -> 4
A9: 8 | B9: Screw М3x12 DIN 967 | C9: ='Applicability of fasteners'!R23 -> 4
A10: 9 | B10: Screw М4x12 DIN 967 | C10: ='Applicability of fasteners'!S23 -> 36
A11: 10 | B11: Screw М4x16 DIN 967 | C11: ='Applicability of fasteners'!T23 -> 10
A12: 11 | B12: Screw М8x25 DIN 967 | C12: ='Applicability of fasteners'!U23 -> 4
A13: 12 | B13: Screw М2x8 DIN 7985 | C13: ='Applicability of fasteners'!V23 -> 8
A14: 13 | B14: Screw М2x16 DIN 7985 | C14: ='Applicability of fasteners'!W23 -> 4
A15: 14 | B15: Screw М2,5x6 DIN 7985 | C15: ='Applicability of fasteners'!X23 -> 4
A16: 15 | B16: Screw М3x8 DIN 7985 | C16: ='Applicability of fasteners'!Y23 -> 10
A17: 16 | B17: Screw М4x16 DIN 7985 | C17: ='Applicability of fasteners'!Z23 -> 4
A18: 17 | B18: Nut M2 DIN 934 | C18: ='Applicability of fasteners'!AA23 -> 12
A19: 18 | B19: Nut M3 DIN 934 | C19: ='Applicability of fasteners'!AB23 -> 14
A20: 19 | B20: Nut M10 DIN 934 | C20: ='Applicability of fasteners'!AC23 -> 8
A21: 20 | B21: Blind Rivet Nut - Round Thin - Stainless Steel - M4 | C21: ='Applicability of fasteners'!F23 -> 58
A22: 21 | B22: Blind Rivet Nut - Round Thin - Stainless Steel - M5 | C22: ='Applicability of fasteners'!G23 -> 48
A23: 22 | B23: Blind Rivet Nut - Round Thin - Stainless Steel - M6 | C23: ='Applicability of fasteners'!H23 -> 16
A24: 23 | B24: Blind Rivet Nut - Round Thin - Stainless Steel - M8 | C24: ='Applicability of fasteners'!I23 -> 8
A25: 24 | B25: Blind rivet Al/St 4,0х8, DIN 7337 | C25: ='Applicability of fasteners'!J23 -> 16
A26: 25 | B26: Washer 2 DIN 125 | C26: ='Applicability of fasteners'!AD23 -> 4
A27: 26 | B27: Washer 2,5 DIN 125 | C27: ='Applicability of fasteners'!AE23 -> 4
A28: 27 | B28: Washer 3 DIN 125 | C28: ='Applicability of fasteners'!AF23 -> 36
A29: 28 | B29: Washer 4 DIN 125 | C29: ='Applicability of fasteners'!AG23 -> 4
A30: 29 | B30: Washer 5 DIN 125 | C30: ='Applicability of fasteners'!AH23 -> 48
A31: 30 | B31: Washer 6 DIN 125 | C31: ='Applicability of fasteners'!AI23 -> 16
A32: 31 | B32: Washer 8 DIN 125 | C32: ='Applicability of fasteners'!AJ23 -> 4
A33: 32 | B33: Washer 10 DIN 125 | C33: ='Applicability of fasteners'!AK23 -> 12
A34: 33 | B34: Spring lock washer 2 DIN 7980 | C34: ='Applicability of fasteners'!AL23 -> 4
A35: 34 | B35: Spring lock washer 2,5 DIN 7980 | C35: ='Applicability of fasteners'!AM23 -> 4
A36: 35 | B36: Spring lock washer 3 DIN 7980 | C36: ='Applicability of fasteners'!AN23 -> 10
A37: 36 | B37: Spring lock washer 4 DIN 7980 | C37: ='Applicability of fasteners'!AO23 -> 12
A38: 37 | B38: Spring lock washer 5 DIN 7980 | C38: ='Applicability of fasteners'!AP23 -> 32
A39: 38 | B39: Spring lock washer 6 DIN 7980 | C39: ='Applicability of fasteners'!AQ23 -> 16
A40: 39 | B40: Spring lock washer 10 DIN 7980 | C40: ='Applicability of fasteners'!AR23 -> 8
...

Sheet Assembly nuances
A1: № | B1: Description
A2: 1 | B2: Sheet metal parts vary by production. Currently, the parts are designed for the following coefficients and radii: K=0.47: sheet 0.8 mm - R=1.2; sheet 1.2 mm - R=1.5; sheet 2.0 mm - R=2.4.
A3: 2 | B3: After bending, parts could be painted.
A4: 3 | B4: After painting, we install riveting nuts. It is allowed to install riveting nuts before painting, provided that the threaded part of the nuts is protected from coating.
A5: 4 | B5: Screws installed without lock washers - fix with a thread lock (eg Loxeal 55-03).
A6: 5 | B6: There may be nuances with block bearings. All details are strongly interconnected and depend on each other.
